Workbook

Sheet Dashboard
B2: Average Score (Across 18 Holes): | C2: ='Avg Score Each Hole'!B22 -> 24.2
B4: An average score per round of 24.2 is ordinary for someone who has been playing golf reguarly for 2 to 3 years
E12: Hole 3 and 18 have the lowest number of puts, these holes are both in the 300 yards range and are in the 10 hardest holes (stroke index 10), the entry to the green is difficult so I'm usually not in a good place on the green | G12: Holes 1, 2, 9, 13, 15 are the holes I put the most on, this could be due to starting slowly and more slopier greens on the back 9
F14: I score the best on par 3's but very closely by the par 5's. I think this is due to the par 5's being particularly small and myself performing better when there are less yards needed per shot | L14: Hole 15 is clearly a hole I need to work on to bring my average score down, this could easily bring my overall score down by playing it safe, avoiding potential hazards, changing the clubs used as it is consistently my worst hole. However, I seem to always recover well on the last holes as well as my score flucturates early in the round possibly due to not warming up properly.

Sheet Pivot Table Average Put
A3: HoleID | B3: Average of Number of Puts
A4: 1 | B4: 2.4
A5: 2 | B5: 2.4
A6: 3 | B6: 1.6
A7: 4 | B7: 2
A8: 5 | B8: 2
A9: 6 | B9: 2.2
A10: 7 | B10: 1.8
A11: 8 | B11: 1.8
A12: 9 | B12: 2.4
A13: 10 | B13: 1.8
A14: 11 | B14: 1.8
A15: 12 | B15: 2
... A21: 18 | B21: 1.6

Sheet Score VS Par
A3: Par | B3: Average of Score
A4: 3 | B4: 1.28
A5: 4 | B5: 1.4
A6: 5 | B6: 1.3

Sheet Avg Score Each Hole
A3: HoleID | B3: Average of Score
A4: 1 | B4: 1.2
A5: 2 | B5: 1.6
A6: 3 | B6: 1
A7: 4 | B7: 1.6
A8: 5 | B8: 1.2
A9: 6 | B9: 1.8
A10: 7 | B10: 1.4
A11: 8 | B11: 1.4
A12: 9 | B12: 1.8
A13: 10 | B13: 0.8
A14: 11 | B14: 1.6
A15: 12 | B15: 1.8
... A21: 18 | B21: 0.8
A22: Total | B22: =SUM(B4:B21) -> 24.2

Sheet Score Sheet
A1: Round Date | B1: HoleID | C1: Par | D1: Yards | E1: Stroke Index | F1: Strokes | G1: Score | H1: Number of Puts
A2: 46143 | B2: 1 | C2: =_xlfn.XLOOKUP(B2, 'Course Table'!A:A, 'Course Table'!B:B) -> 5 | D2: =_xlfn.XLOOKUP(B2, 'Course Table'!A:A, 'Course Table'!C:C) -> 446 | E2: =_xlfn.XLOOKUP(B2, 'Course Table'!A:A, 'Course Table'!D:D) -> 11 | F2: 7 | G2: =F2-C2 -> 2 | H2: 3
A3: =A2 -> 46143 | B3: 2 | C3: =_xlfn.XLOOKUP(B3, 'Course Table'!A:A, 'Course Table'!B:B) -> 3 | D3: =_xlfn.XLOOKUP(B3, 'Course Table'!A:A, 'Course Table'!C:C) -> 178 | E3: =_xlfn.XLOOKUP(B3, 'Course Table'!A:A, 'Course Table'!D:D) -> 7 | F3: 5 | G3: =F3-C3 -> 2 | H3: 2
A4: =A3 -> 46143 | B4: 3 | C4: =_xlfn.XLOOKUP(B4, 'Course Table'!A:A, 'Course Table'!B:B) -> 4 | D4: =_xlfn.XLOOKUP(B4, 'Course Table'!A:A, 'Course Table'!C:C) -> 370 | E4: =_xlfn.XLOOKUP(B4, 'Course Table'!A:A, 'Course Table'!D:D) -> 5 | F4: 4 | G4: =F4-C4 -> 0 | H4: 1
A5: =A4 -> 46143 | B5: 4 | C5: =_xlfn.XLOOKUP(B5, 'Course Table'!A:A, 'Course Table'!B:B) -> 4 | D5: =_xlfn.XLOOKUP(B5, 'Course Table'!A:A, 'Course Table'!C:C) -> 379 | E5: =_xlfn.XLOOKUP(B5, 'Course Table'!A:A, 'Course Table'!D:D) -> 13 | F5: 5 | G5: =F5-C5 -> 1 | H5: 2
A6: =A5 -> 46143 | B6: 5 | C6: =_xlfn.XLOOKUP(B6, 'Course Table'!A:A, 'Course Table'!B:B) -> 5 | D6: =_xlfn.XLOOKUP(B6, 'Course Table'!A:A, 'Course Table'!C:C) -> 519 | E6: =_xlfn.XLOOKUP(B6, 'Course Table'!A:A, 'Course Table'!D:D) -> 1 | F6: 7 | G6: =F6-C6 -> 2 | H6: 3
A7: =A6 -> 46143 | B7: 6 | C7: =_xlfn.XLOOKUP(B7, 'Course Table'!A:A, 'Course Table'!B:B) -> 3 | D7: =_xlfn.XLOOKUP(B7, 'Course Table'!A:A, 'Course Table'!C:C) -> 154 | E7: =_xlfn.XLOOKUP(B7, 'Course Table'!A:A, 'Course Table'!D:D) -> 17 | F7: 6 | G7: =F7-C7 -> 3 | H7: 2
A8: =A7 -> 46143 | B8: 7 | C8: =_xlfn.XLOOKUP(B8, 'Course Table'!A:A, 'Course Table'!B:B) -> 4 | D8: =_xlfn.XLOOKUP(B8, 'Course Table'!A:A, 'Course Table'!C:C) -> 262 | E8: =_xlfn.XLOOKUP(B8, 'Course Table'!A:A, 'Course Table'!D:D) -> 15 | F8: 6 | G8: =F8-C8 -> 2 | H8: 2
A9: =A8 -> 46143 | B9: 8 | C9: =_xlfn.XLOOKUP(B9, 'Course Table'!A:A, 'Course Table'!B:B) -> 4 | D9: =_xlfn.XLOOKUP(B9, 'Course Table'!A:A, 'Course Table'!C:C) -> 407 | E9: =_xlfn.XLOOKUP(B9, 'Course Table'!A:A, 'Course Table'!D:D) -> 3 | F9: 5 | G9: =F9-C9 -> 1 | H9: 1
A10: =A9 -> 46143 | B10: 9 | C10: =_xlfn.XLOOKUP(B10, 'Course Table'!A:A, 'Course Table'!B:B) -> 5 | D10: =_xlfn.XLOOKUP(B10, 'Course Table'!A:A, 'Course Table'!C:C) -> 452 | E10: =_xlfn.XLOOKUP(B10, 'Course Table'!A:A, 'Course Table'!D:D) -> 9 | F10: 8 | G10: =F10-C10 -> 3 | H10: 4
A11: =A10 -> 46143 | B11: 10 | C11: =_xlfn.XLOOKUP(B11, 'Course Table'!A:A, 'Course Table'!B:B) -> 3 | D11: =_xlfn.XLOOKUP(B11, 'Course Table'!A:A, 'Course Table'!C:C) -> 187 | E11: =_xlfn.XLOOKUP(B11, 'Course Table'!A:A, 'Course Table'!D:D) -> 12 | F11: 4 | G11: =F11-C11 -> 1 | H11: 2
A12: =A11 -> 46143 | B12: 11 | C12: =_xlfn.XLOOKUP(B12, 'Course Table'!A:A, 'Course Table'!B:B) -> 4 | D12: =_xlfn.XLOOKUP(B12, 'Course Table'!A:A, 'Course Table'!C:C) -> 369 | E12: =_xlfn.XLOOKUP(B12, 'Course Table'!A:A, 'Course Table'!D:D) -> 4 | F12: 6 | G12: =F12-C12 -> 2 | H12: 3
A13: =A12 -> 46143 | B13: 12 | C13: =_xlfn.XLOOKUP(B13, 'Course Table'!A:A, 'Course Table'!B:B) -> 4 | D13: =_xlfn.XLOOKUP(B13, 'Course Table'!A:A, 'Course Table'!C:C) -> 346 | E13: =_xlfn.XLOOKUP(B13, 'Course Table'!A:A, 'Course Table'!D:D) -> 8 | F13: 6 | G13: =F13-C13 -> 2 | H13: 2
A14: =A13 -> 46143 | B14: 13 | C14: =_xlfn.XLOOKUP(B14, 'Course Table'!A:A, 'Course Table'!B:B) -> 3 | D14: =_xlfn.XLOOKUP(B14, 'Course Table'!A:A, 'Course Table'!C:C) -> 159 | E14: =_xlfn.XLOOKUP(B14, 'Course Table'!A:A, 'Course Table'!D:D) -> 18 | F14: 4 | G14: =F14-C14 -> 1 | H14: 1
... A19: =A18 -> 46143 | B19: 18 | C19: =_xlfn.XLOOKUP(B19, 'Course Table'!A:A, 'Course Table'!B:B) -> 4 | D19: =_xlfn.XLOOKUP(B19, 'Course Table'!A:A, 'Course Table'!C:C) -> 338 | E19: =_xlfn.XLOOKUP(B19, 'Course Table'!A:A, 'Course Table'!D:D) -> 10 | F19: 4 | G19: =F19-C19 -> 0 | H19: 1
A20: 46149 | B20: 1 | C20: =_xlfn.XLOOKUP(B20, 'Course Table'!A:A, 'Course Table'!B:B) -> 5 | D20: =_xlfn.XLOOKUP(B20, 'Course Table'!A:A, 'Course Table'!C:C) -> 446 | E20: =_xlfn.XLOOKUP(B20, 'Course Table'!A:A, 'Course Table'!D:D) -> 11 | F20: 6 | G20: =F20-C20 -> 1 | H20: 2
A21: =A20 -> 46149 | B21: 2 | C21: =_xlfn.XLOOKUP(B21, 'Course Table'!A:A, 'Course Table'!B:B) -> 3 | D21: =_xlfn.XLOOKUP(B21, 'Course Table'!A:A, 'Course Table'!C:C) -> 178 | E21: =_xlfn.XLOOKUP(B21, 'Course Table'!A:A, 'Course Table'!D:D) -> 7 | F21: 5 | G21: =F21-C21 -> 2 | H21: 3
A22: =A21 -> 46149 | B22: 3 | C22: =_xlfn.XLOOKUP(B22, 'Course Table'!A:A, 'Course Table'!B:B) -> 4 | D22: =_xlfn.XLOOKUP(B22, 'Course Table'!A:A, 'Course Table'!C:C) -> 370 | E22: =_xlfn.XLOOKUP(B22, 'Course Table'!A:A, 'Course Table'!D:D) -> 5 | F22: 5 | G22: =F22-C22 -> 1 | H22: 1
A23: =A22 -> 46149 | B23: 4 | C23: =_xlfn.XLOOKUP(B23, 'Course Table'!A:A, 'Course Table'!B:B) -> 4 | D23: =_xlfn.XLOOKUP(B23, 'Course Table'!A:A, 'Course Table'!C:C) -> 379 | E23: =_xlfn.XLOOKUP(B23, 'Course Table'!A:A, 'Course Table'!D:D) -> 13 | F23: 6 | G23: =F23-C23 -> 2 | H23: 2
A24: =A23 -> 46149 | B24: 5 | C24: =_xlfn.XLOOKUP(B24, 'Course Table'!A:A, 'Course Table'!B:B) -> 5 | D24: =_xlfn.XLOOKUP(B24, 'Course Table'!A:A, 'Course Table'!C:C) -> 519 | E24: =_xlfn.XLOOKUP(B24, 'Course Table'!A:A, 'Course Table'!D:D) -> 1 | F24: 6 | G24: =F24-C24 -> 1 | H24: 2
A25: =A24 -> 46149 | B25: 6 | C25: =_xlfn.XLOOKUP(B25, 'Course Table'!A:A, 'Course Table'!B:B) -> 3 | D25: =_xlfn.XLOOKUP(B25, 'Course Table'!A:A, 'Course Table'!C:C) -> 154 | E25: =_xlfn.XLOOKUP(B25, 'Course Table'!A:A, 'Course Table'!D:D) -> 17 | F25: 4 | G25: =F25-C25 -> 1 | H25: 2
A26: =A25 -> 46149 | B26: 7 | C26: =_xlfn.XLOOKUP(B26, 'Course Table'!A:A, 'Course Table'!B:B) -> 4 | D26: =_xlfn.XLOOKUP(B26, 'Course Table'!A:A, 'Course Table'!C:C) -> 262 | E26: =_xlfn.XLOOKUP(B26, 'Course Table'!A:A, 'Course Table'!D:D) -> 15 | F26: 6 | G26: =F26-C26 -> 2 | H26: 2
A27: =A26 -> 46149 | B27: 8 | C27: =_xlfn.XLOOKUP(B27, 'Course Table'!A:A, 'Course Table'!B:B) -> 4 | D27: =_xlfn.XLOOKUP(B27, 'Course Table'!A:A, 'Course Table'!C:C) -> 407 | E27: =_xlfn.XLOOKUP(B27, 'Course Table'!A:A, 'Course Table'!D:D) -> 3 | F27: 7 | G27: =F27-C27 -> 3 | H27: 3
A28: =A27 -> 46149 | B28: 9 | C28: =_xlfn.XLOOKUP(B28, 'Course Table'!A:A, 'Course Table'!B:B) -> 5 | D28: =_xlfn.XLOOKUP(B28, 'Course Table'!A:A, 'Course Table'!C:C) -> 452 | E28: =_xlfn.XLOOKUP(B28, 'Course Table'!A:A, 'Course Table'!D:D) -> 9 | F28: 7 | G28: =F28-C28 -> 2 | H28: 2
A29: =A28 -> 46149 | B29: 10 | C29: =_xlfn.XLOOKUP(B29, 'Course Table'!A:A, 'Course Table'!B:B) -> 3 | D29: =_xlfn.XLOOKUP(B29, 'Course Table'!A:A, 'Course Table'!C:C) -> 187 | E29: =_xlfn.XLOOKUP(B29, 'Course Table'!A:A, 'Course Table'!D:D) -> 12 | F29: 3 | G29: =F29-C29 -> 0 | H29: 1
A30: =A29 -> 46149 | B30: 11 | C30: =_xlfn.XLOOKUP(B30, 'Course Table'!A:A, 'Course Table'!B:B) -> 4 | D30: =_xlfn.XLOOKUP(B30, 'Course Table'!A:A, 'Course Table'!C:C) -> 369 | E30: =_xlfn.XLOOKUP(B30, 'Course Table'!A:A, 'Course Table'!D:D) -> 4 | F30: 6 | G30: =F30-C30 -> 2 | H30: 1
A31: =A30 -> 46149 | B31: 12 | C31: =_xlfn.XLOOKUP(B31, 'Course Table'!A:A, 'Course Table'!B:B) -> 4 | D31: =_xlfn.XLOOKUP(B31, 'Course Table'!A:A, 'Course Table'!C:C) -> 346 | E31: =_xlfn.XLOOKUP(B31, 'Course Table'!A:A, 'Course Table'!D:D) -> 8 | F31: 6 | G31: =F31-C31 -> 2 | H31: 2
A32: =A31 -> 46149 | B32: 13 | C32: =_xlfn.XLOOKUP(B32, 'Course Table'!A:A, 'Course Table'!B:B) -> 3 | D32: =_xlfn.XLOOKUP(B32, 'Course Table'!A:A, 'Course Table'!C:C) -> 159 | E32: =_xlfn.XLOOKUP(B32, 'Course Table'!A:A, 'Course Table'!D:D) -> 18 | F32: 5 | G32: =F32-C32 -> 2 | H32: 3
... A37: =A36 -> 46149 | B37: 18 | C37: =_xlfn.XLOOKUP(B37, 'Course Table'!A:A, 'Course Table'!B:B) -> 4 | D37: =_xlfn.XLOOKUP(B37, 'Course Table'!A:A, 'Course Table'!C:C) -> 338 | E37: =_xlfn.XLOOKUP(B37, 'Course Table'!A:A, 'Course Table'!D:D) -> 10 | F37: 5 | G37: =F37-C37 -> 1 | H37: 2
A38: 46156 | B38: 1 | C38: =_xlfn.XLOOKUP(B38, 'Course Table'!A:A, 'Course Table'!B:B) -> 5 | D38: =_xlfn.XLOOKUP(B38, 'Course Table'!A:A, 'Course Table'!C:C) -> 446 | E38: =_xlfn.XLOOKUP(B38, 'Course Table'!A:A, 'Course Table'!D:D) -> 11 | F38: 6 | G38: =F38-C38 -> 1 | H38: 3
A39: =A38 -> 46156 | B39: 2 | C39: =_xlfn.XLOOKUP(B39, 'Course Table'!A:A, 'Course Table'!B:B) -> 3 | D39: =_xlfn.XLOOKUP(B39, 'Course Table'!A:A, 'Course Table'!C:C) -> 178 | E39: =_xlfn.XLOOKUP(B39, 'Course Table'!A:A, 'Course Table'!D:D) -> 7 | F39: 4 | G39: =F39-C39 -> 1 | H39: 2
A40: =A39 -> 46156 | B40: 3 | C40: =_xlfn.XLOOKUP(B40, 'Course Table'!A:A, 'Course Table'!B:B) -> 4 | D40: =_xlfn.XLOOKUP(B40, 'Course Table'!A:A, 'Course Table'!C:C) -> 370 | E40: =_xlfn.XLOOKUP(B40, 'Course Table'!A:A, 'Course Table'!D:D) -> 5 | F40: 6 | G40: =F40-C40 -> 2 | H40: 2
A41: =A40 -> 46156 | B41: 4 | C41: =_xlfn.XLOOKUP(B41, 'Course Table'!A:A, 'Course Table'!B:B) -> 4 | D41: =_xlfn.XLOOKUP(B41, 'Course Table'!A:A, 'Course Table'!C:C) -> 379 | E41: =_xlfn.XLOOKUP(B41, 'Course Table'!A:A, 'Course Table'!D:D) -> 13 | F41: 6 | G41: =F41-C41 -> 2 | H41: 2
A42: =A41 -> 46156 | B42: 5 | C42: =_xlfn.XLOOKUP(B42, 'Course Table'!A:A, 'Course Table'!B:B) -> 5 | D42: =_xlfn.XLOOKUP(B42, 'Course Table'!A:A, 'Course Table'!C:C) -> 519 | E42: =_xlfn.XLOOKUP(B42, 'Course Table'!A:A, 'Course Table'!D:D) -> 1 | F42: 7 | G42: =F42-C42 -> 2 | H42: 2
A43: =A42 -> 46156 | B43: 6 | C43: =_xlfn.XLOOKUP(B43, 'Course Table'!A:A, 'Course Table'!B:B) -> 3 | D43: =_xlfn.XLOOKUP(B43, 'Course Table'!A:A, 'Course Table'!C:C) -> 154 | E43: =_xlfn.XLOOKUP(B43, 'Course Table'!A:A, 'Course Table'!D:D) -> 17 | F43: 5 | G43: =F43-C43 -> 2 | H43: 3
A44: =A43 -> 46156 | B44: 7 | C44: =_xlfn.XLOOKUP(B44, 'Course Table'!A:A, 'Course Table'!B:B) -> 4 | D44: =_xlfn.XLOOKUP(B44, 'Course Table'!A:A, 'Course Table'!C:C) -> 262 | E44: =_xlfn.XLOOKUP(B44, 'Course Table'!A:A, 'Course Table'!D:D) -> 15 | F44: 4 | G44: =F44-C44 -> 0 | H44: 1
A45: =A44 -> 46156 | B45: 8 | C45: =_xlfn.XLOOKUP(B45, 'Course Table'!A:A, 'Course Table'!B:B) -> 4 | D45: =_xlfn.XLOOKUP(B45, 'Course Table'!A:A, 'Course Table'!C:C) -> 407 | E45: =_xlfn.XLOOKUP(B45, 'Course Table'!A:A, 'Course Table'!D:D) -> 3 | F45: 5 | G45: =F45-C45 -> 1 | H45: 2
A46: =A45 -> 46156 | B46: 9 | C46: =_xlfn.XLOOKUP(B46, 'Course Table'!A:A, 'Course Table'!B:B) -> 5 | D46: =_xlfn.XLOOKUP(B46, 'Course Table'!A:A, 'Course Table'!C:C) -> 452 | E46: =_xlfn.XLOOKUP(B46, 'Course Table'!A:A, 'Course Table'!D:D) -> 9 | F46: 6 | G46: =F46-C46 -> 1 | H46: 1
A47: =A46 -> 46156 | B47: 10 | C47: =_xlfn.XLOOKUP(B47, 'Course Table'!A:A, 'Course Table'!B:B) -> 3 | D47: =_xlfn.XLOOKUP(B47, 'Course Table'!A:A, 'Course Table'!C:C) -> 187 | E47: =_xlfn.XLOOKUP(B47, 'Course Table'!A:A, 'Course Table'!D:D) -> 12 | F47: 6 | G47: =F47-C47 -> 3 | H47: 3
A48: =A47 -> 46156 | B48: 11 | C48: =_xlfn.XLOOKUP(B48, 'Course Table'!A:A, 'Course Table'!B:B) -> 4 | D48: =_xlfn.XLOOKUP(B48, 'Course Table'!A:A, 'Course Table'!C:C) -> 369 | E48: =_xlfn.XLOOKUP(B48, 'Course Table'!A:A, 'Course Table'!D:D) -> 4 | F48: 6 | G48: =F48-C48 -> 2 | H48: 2
...

Sheet Course Table
A1: HoleID | B1: Par | C1: Yards | D1: Stroke Index
A2: 1 | B2: 5 | C2: 446 | D2: 11
A3: 2 | B3: 3 | C3: 178 | D3: 7
A4: 3 | B4: 4 | C4: 370 | D4: 5
A5: 4 | B5: 4 | C5: 379 | D5: 13
A6: 5 | B6: 5 | C6: 519 | D6: 1
A7: 6 | B7: 3 | C7: 154 | D7: 17
A8: 7 | B8: 4 | C8: 262 | D8: 15
A9: 8 | B9: 4 | C9: 407 | D9: 3
A10: 9 | B10: 5 | C10: 452 | D10: 9
A11: 10 | B11: 3 | C11: 187 | D11: 12
A12: 11 | B12: 4 | C12: 369 | D12: 4
A13: 12 | B13: 4 | C13: 346 | D13: 8
... A19: 18 | B19: 4 | C19: 338 | D19: 10
